{
  "comments": [
    {
      "key": {
        "uuid": "87912bd0_2c602c2e",
        "filename": "extensions/phal/phal_error.cpp",
        "patchSetId": 5
      },
      "lineNbr": 585,
      "author": {
        "id": 1000084
      },
      "writtenOn": "2021-10-13T16:24:14Z",
      "side": 1,
      "message": "do we need catch the exception here? it is already in the error path.",
      "revId": "0a07a815920c4a6f33c773b928a6de27f5f42b53",
      "serverId": "adbd0a64-1f21-4d83-b585-671fe73cb6e4",
      "unresolved": true
    }
  ]
}